Workbook

Sheet Gantt
A2: SmartStorage — Diagrama de Gantt
A3: Agosto–noviembre de 2026. Cada columna representa una semana que inicia el lunes; las barras muestran fechas planificadas.
A4: Azul: propuesta y diseño. Verde: avances funcionales. Naranja: cierre. H: semana de entrega. Editar fechas en Tareas.
A5: Ver “Detalle 30%” para el calendario diario del primer avance. El color de una barra no indica tarea terminada.
A6: Los alcances de 50%, 80% y cierre son una propuesta. La fecha final del 06/11 queda pendiente de confirmación.
A7: ID / hito | B7: Actividad | C7: Responsable | D7: Inicio | E7: Fin | F7: Estado reportado | G7: 46258 | H7: 46265 | I7: 46272 | J7: 46279 | K7: 46286 | L7: 46293 | M7: 46300 | N7: 46307 | O7: 46314 | P7: 46321 | Q7: 46328
A8: ='Entregas y equipo'!A8 -> S0 | B8: ='Entregas y equipo'!B8 -> Coordinación y propuesta | C8: ="Equipo" -> Equipo | D8: ='Entregas y equipo'!C8 -> 46258 | E8: ='Entregas y equipo'!D8 -> 46262 | F8: ="Hito previsto" -> Hito previsto | G8: =IF(AND(G$7<=$E8,G$7+6>=$E8),"H",IF(AND(G$7<=$E8,G$7+6>=$D8),1,"")) -> H | H8: =IF(AND(H$7<=$E8,H$7+6>=$E8),"H",IF(AND(H$7<=$E8,H$7+6>=$D8),1,"")) | I8: =IF(AND(I$7<=$E8,I$7+6>=$E8),"H",IF(AND(I$7<=$E8,I$7+6>=$D8),1,"")) | J8: =IF(AND(J$7<=$E8,J$7+6>=$E8),"H",IF(AND(J$7<=$E8,J$7+6>=$D8),1,"")) | K8: =IF(AND(K$7<=$E8,K$7+6>=$E8),"H",IF(AND(K$7<=$E8,K$7+6>=$D8),1,"")) | L8: =IF(AND(L$7<=$E8,L$7+6>=$E8),"H",IF(AND(L$7<=$E8,L$7+6>=$D8),1,"")) | M8: =IF(AND(M$7<=$E8,M$7+6>=$E8),"H",IF(AND(M$7<=$E8,M$7+6>=$D8),1,"")) | N8: =IF(AND(N$7<=$E8,N$7+6>=$E8),"H",IF(AND(N$7<=$E8,N$7+6>=$D8),1,"")) | ... Q8: =IF(AND(Q$7<=$E8,Q$7+6>=$E8),"H",IF(AND(Q$7<=$E8,Q$7+6>=$D8),1,""))
A9: S0-01 | B9: =VLOOKUP($A9,Tareas!$A$8:$P$63,4,FALSE) -> Definir equipo y organización | C9: =VLOOKUP($A9,Tareas!$A$8:$P$63,5,FALSE) -> Equipo | D9: =VLOOKUP($A9,Tareas!$A$8:$P$63,7,FALSE) -> 46258 | E9: =VLOOKUP($A9,Tareas!$A$8:$P$63,8,FALSE) -> 46259 | F9: Confirmado | G9: =IF(AND(G$7<=$E9,G$7+6>=$D9),1,"") -> 1 | H9: =IF(AND(H$7<=$E9,H$7+6>=$D9),1,"") | I9: =IF(AND(I$7<=$E9,I$7+6>=$D9),1,"") | J9: =IF(AND(J$7<=$E9,J$7+6>=$D9),1,"") | K9: =IF(AND(K$7<=$E9,K$7+6>=$D9),1,"") | L9: =IF(AND(L$7<=$E9,L$7+6>=$D9),1,"") | M9: =IF(AND(M$7<=$E9,M$7+6>=$D9),1,"") | N9: =IF(AND(N$7<=$E9,N$7+6>=$D9),1,"") | ... Q9: =IF(AND(Q$7<=$E9,Q$7+6>=$D9),1,"")
A10: S0-02 | B10: =VLOOKUP($A10,Tareas!$A$8:$P$63,4,FALSE) -> Definir problema, solución y alcance | C10: =VLOOKUP($A10,Tareas!$A$8:$P$63,5,FALSE) -> Equipo | D10: =VLOOKUP($A10,Tareas!$A$8:$P$63,7,FALSE) -> 46259 | E10: =VLOOKUP($A10,Tareas!$A$8:$P$63,8,FALSE) -> 46261 | F10: Confirmado | G10: =IF(AND(G$7<=$E10,G$7+6>=$D10),1,"") -> 1 | H10: =IF(AND(H$7<=$E10,H$7+6>=$D10),1,"") | I10: =IF(AND(I$7<=$E10,I$7+6>=$D10),1,"") | J10: =IF(AND(J$7<=$E10,J$7+6>=$D10),1,"") | K10: =IF(AND(K$7<=$E10,K$7+6>=$D10),1,"") | L10: =IF(AND(L$7<=$E10,L$7+6>=$D10),1,"") | M10: =IF(AND(M$7<=$E10,M$7+6>=$D10),1,"") | N10: =IF(AND(N$7<=$E10,N$7+6>=$D10),1,"") | ... Q10: =IF(AND(Q$7<=$E10,Q$7+6>=$D10),1,"")
A11: S0-03 | B11: =VLOOKUP($A11,Tareas!$A$8:$P$63,4,FALSE) -> Preparar metodología y cronograma | C11: =VLOOKUP($A11,Tareas!$A$8:$P$63,5,FALSE) -> Equipo | D11: =VLOOKUP($A11,Tareas!$A$8:$P$63,7,FALSE) -> 46260 | E11: =VLOOKUP($A11,Tareas!$A$8:$P$63,8,FALSE) -> 46261 | F11: Confirmado | G11: =IF(AND(G$7<=$E11,G$7+6>=$D11),1,"") -> 1 | H11: =IF(AND(H$7<=$E11,H$7+6>=$D11),1,"") | I11: =IF(AND(I$7<=$E11,I$7+6>=$D11),1,"") | J11: =IF(AND(J$7<=$E11,J$7+6>=$D11),1,"") | K11: =IF(AND(K$7<=$E11,K$7+6>=$D11),1,"") | L11: =IF(AND(L$7<=$E11,L$7+6>=$D11),1,"") | M11: =IF(AND(M$7<=$E11,M$7+6>=$D11),1,"") | N11: =IF(AND(N$7<=$E11,N$7+6>=$D11),1,"") | ... Q11: =IF(AND(Q$7<=$E11,Q$7+6>=$D11),1,"")
A12: S0-04 | B12: =VLOOKUP($A12,Tareas!$A$8:$P$63,4,FALSE) -> Revisar y entregar propuesta | C12: =VLOOKUP($A12,Tareas!$A$8:$P$63,5,FALSE) -> Equipo | D12: =VLOOKUP($A12,Tareas!$A$8:$P$63,7,FALSE) -> 46262 | E12: =VLOOKUP($A12,Tareas!$A$8:$P$63,8,FALSE) -> 46262 | F12: Confirmado | G12: =IF(AND(G$7<=$E12,G$7+6>=$D12),1,"") -> 1 | H12: =IF(AND(H$7<=$E12,H$7+6>=$D12),1,"") | I12: =IF(AND(I$7<=$E12,I$7+6>=$D12),1,"") | J12: =IF(AND(J$7<=$E12,J$7+6>=$D12),1,"") | K12: =IF(AND(K$7<=$E12,K$7+6>=$D12),1,"") | L12: =IF(AND(L$7<=$E12,L$7+6>=$D12),1,"") | M12: =IF(AND(M$7<=$E12,M$7+6>=$D12),1,"") | N12: =IF(AND(N$7<=$E12,N$7+6>=$D12),1,"") | ... Q12: =IF(AND(Q$7<=$E12,Q$7+6>=$D12),1,"")
A13: ='Entregas y equipo'!A9 -> S1 | B13: ='Entregas y equipo'!B9 -> Requisitos y diseño preliminar | C13: ="Equipo" -> Equipo | D13: ='Entregas y equipo'!C9 -> 46263 | E13: ='Entregas y equipo'!D9 -> 46276 | F13: ="Hito previsto" -> Hito previsto | G13: =IF(AND(G$7<=$E13,G$7+6>=$E13),"H",IF(AND(G$7<=$E13,G$7+6>=$D13),1,"")) -> 1 | H13: =IF(AND(H$7<=$E13,H$7+6>=$E13),"H",IF(AND(H$7<=$E13,H$7+6>=$D13),1,"")) -> 1 | I13: =IF(AND(I$7<=$E13,I$7+6>=$E13),"H",IF(AND(I$7<=$E13,I$7+6>=$D13),1,"")) -> H | J13: =IF(AND(J$7<=$E13,J$7+6>=$E13),"H",IF(AND(J$7<=$E13,J$7+6>=$D13),1,"")) | K13: =IF(AND(K$7<=$E13,K$7+6>=$E13),"H",IF(AND(K$7<=$E13,K$7+6>=$D13),1,"")) | L13: =IF(AND(L$7<=$E13,L$7+6>=$E13),"H",IF(AND(L$7<=$E13,L$7+6>=$D13),1,"")) | M13: =IF(AND(M$7<=$E13,M$7+6>=$E13),"H",IF(AND(M$7<=$E13,M$7+6>=$D13),1,"")) | N13: =IF(AND(N$7<=$E13,N$7+6>=$E13),"H",IF(AND(N$7<=$E13,N$7+6>=$D13),1,"")) | ... Q13: =IF(AND(Q$7<=$E13,Q$7+6>=$E13),"H",IF(AND(Q$7<=$E13,Q$7+6>=$D13),1,""))
A14: S1-01 | B14: =VLOOKUP($A14,Tareas!$A$8:$P$63,4,FALSE) -> Detallar requisitos de usuarios | C14: =VLOOKUP($A14,Tareas!$A$8:$P$63,5,FALSE) -> Andy | D14: =VLOOKUP($A14,Tareas!$A$8:$P$63,7,FALSE) -> 46265 | E14: =VLOOKUP($A14,Tareas!$A$8:$P$63,8,FALSE) -> 46268 | F14: =VLOOKUP($A14,Tareas!$A$8:$P$63,11,FALSE) -> Hecha | G14: =IF(AND(G$7<=$E14,G$7+6>=$D14),1,"") | H14: =IF(AND(H$7<=$E14,H$7+6>=$D14),1,"") -> 1 | I14: =IF(AND(I$7<=$E14,I$7+6>=$D14),1,"") | J14: =IF(AND(J$7<=$E14,J$7+6>=$D14),1,"") | K14: =IF(AND(K$7<=$E14,K$7+6>=$D14),1,"") | L14: =IF(AND(L$7<=$E14,L$7+6>=$D14),1,"") | M14: =IF(AND(M$7<=$E14,M$7+6>=$D14),1,"") | N14: =IF(AND(N$7<=$E14,N$7+6>=$D14),1,"") | ... Q14: =IF(AND(Q$7<=$E14,Q$7+6>=$D14),1,"")
A15: S1-02 | B15: =VLOOKUP($A15,Tareas!$A$8:$P$63,4,FALSE) -> Detallar requisitos de Storage | C15: =VLOOKUP($A15,Tareas!$A$8:$P$63,5,FALSE) -> Geovanny | D15: =VLOOKUP($A15,Tareas!$A$8:$P$63,7,FALSE) -> 46265 | E15: =VLOOKUP($A15,Tareas!$A$8:$P$63,8,FALSE) -> 46268 | F15: =VLOOKUP($A15,Tareas!$A$8:$P$63,11,FALSE) -> Hecha | G15: =IF(AND(G$7<=$E15,G$7+6>=$D15),1,"") | H15: =IF(AND(H$7<=$E15,H$7+6>=$D15),1,"") -> 1 | I15: =IF(AND(I$7<=$E15,I$7+6>=$D15),1,"") | J15: =IF(AND(J$7<=$E15,J$7+6>=$D15),1,"") | K15: =IF(AND(K$7<=$E15,K$7+6>=$D15),1,"") | L15: =IF(AND(L$7<=$E15,L$7+6>=$D15),1,"") | M15: =IF(AND(M$7<=$E15,M$7+6>=$D15),1,"") | N15: =IF(AND(N$7<=$E15,N$7+6>=$D15),1,"") | ... Q15: =IF(AND(Q$7<=$E15,Q$7+6>=$D15),1,"")
A16: S1-03 | B16: =VLOOKUP($A16,Tareas!$A$8:$P$63,4,FALSE) -> Detallar planes y pagos simulados | C16: =VLOOKUP($A16,Tareas!$A$8:$P$63,5,FALSE) -> Elden | D16: =VLOOKUP($A16,Tareas!$A$8:$P$63,7,FALSE) -> 46265 | E16: =VLOOKUP($A16,Tareas!$A$8:$P$63,8,FALSE) -> 46268 | F16: =VLOOKUP($A16,Tareas!$A$8:$P$63,11,FALSE) -> Por confirmar | G16: =IF(AND(G$7<=$E16,G$7+6>=$D16),1,"") | H16: =IF(AND(H$7<=$E16,H$7+6>=$D16),1,"") -> 1 | I16: =IF(AND(I$7<=$E16,I$7+6>=$D16),1,"") | J16: =IF(AND(J$7<=$E16,J$7+6>=$D16),1,"") | K16: =IF(AND(K$7<=$E16,K$7+6>=$D16),1,"") | L16: =IF(AND(L$7<=$E16,L$7+6>=$D16),1,"") | M16: =IF(AND(M$7<=$E16,M$7+6>=$D16),1,"") | N16: =IF(AND(N$7<=$E16,N$7+6>=$D16),1,"") | ... Q16: =IF(AND(Q$7<=$E16,Q$7+6>=$D16),1,"")
A17: S1-04 | B17: =VLOOKUP($A17,Tareas!$A$8:$P$63,4,FALSE) -> Diseñar pantallas y navegación | C17: =VLOOKUP($A17,Tareas!$A$8:$P$63,5,FALSE) -> Diego | D17: =VLOOKUP($A17,Tareas!$A$8:$P$63,7,FALSE) -> 46265 | E17: =VLOOKUP($A17,Tareas!$A$8:$P$63,8,FALSE) -> 46273 | F17: =VLOOKUP($A17,Tareas!$A$8:$P$63,11,FALSE) -> Por confirmar | G17: =IF(AND(G$7<=$E17,G$7+6>=$D17),1,"") | H17: =IF(AND(H$7<=$E17,H$7+6>=$D17),1,"") -> 1 | I17: =IF(AND(I$7<=$E17,I$7+6>=$D17),1,"") -> 1 | J17: =IF(AND(J$7<=$E17,J$7+6>=$D17),1,"") | K17: =IF(AND(K$7<=$E17,K$7+6>=$D17),1,"") | L17: =IF(AND(L$7<=$E17,L$7+6>=$D17),1,"") | M17: =IF(AND(M$7<=$E17,M$7+6>=$D17),1,"") | N17: =IF(AND(N$7<=$E17,N$7+6>=$D17),1,"") | ... Q17: =IF(AND(Q$7<=$E17,Q$7+6>=$D17),1,"")
A18: S1-05 | B18: =VLOOKUP($A18,Tareas!$A$8:$P$63,4,FALSE) -> Consolidar modelo de datos y arquitectura | C18: =VLOOKUP($A18,Tareas!$A$8:$P$63,5,FALSE) -> Equipo | D18: =VLOOKUP($A18,Tareas!$A$8:$P$63,7,FALSE) -> 46269 | E18: =VLOOKUP($A18,Tareas!$A$8:$P$63,8,FALSE) -> 46274 | F18: =VLOOKUP($A18,Tareas!$A$8:$P$63,11,FALSE) -> Por confirmar | G18: =IF(AND(G$7<=$E18,G$7+6>=$D18),1,"") | H18: =IF(AND(H$7<=$E18,H$7+6>=$D18),1,"") -> 1 | I18: =IF(AND(I$7<=$E18,I$7+6>=$D18),1,"") -> 1 | J18: =IF(AND(J$7<=$E18,J$7+6>=$D18),1,"") | K18: =IF(AND(K$7<=$E18,K$7+6>=$D18),1,"") | L18: =IF(AND(L$7<=$E18,L$7+6>=$D18),1,"") | M18: =IF(AND(M$7<=$E18,M$7+6>=$D18),1,"") | N18: =IF(AND(N$7<=$E18,N$7+6>=$D18),1,"") | ... Q18: =IF(AND(Q$7<=$E18,Q$7+6>=$D18),1,"")
A19: S1-06 | B19: =VLOOKUP($A19,Tareas!$A$8:$P$63,4,FALSE) -> Revisar requisitos y diseño preliminar | C19: =VLOOKUP($A19,Tareas!$A$8:$P$63,5,FALSE) -> Equipo | D19: =VLOOKUP($A19,Tareas!$A$8:$P$63,7,FALSE) -> 46275 | E19: =VLOOKUP($A19,Tareas!$A$8:$P$63,8,FALSE) -> 46276 | F19: =VLOOKUP($A19,Tareas!$A$8:$P$63,11,FALSE) -> Por confirmar | G19: =IF(AND(G$7<=$E19,G$7+6>=$D19),1,"") | H19: =IF(AND(H$7<=$E19,H$7+6>=$D19),1,"") | I19: =IF(AND(I$7<=$E19,I$7+6>=$D19),1,"") -> 1 | J19: =IF(AND(J$7<=$E19,J$7+6>=$D19),1,"") | K19: =IF(AND(K$7<=$E19,K$7+6>=$D19),1,"") | L19: =IF(AND(L$7<=$E19,L$7+6>=$D19),1,"") | M19: =IF(AND(M$7<=$E19,M$7+6>=$D19),1,"") | N19: =IF(AND(N$7<=$E19,N$7+6>=$D19),1,"") | ... Q19: =IF(AND(Q$7<=$E19,Q$7+6>=$D19),1,"")
A20: ='Entregas y equipo'!A10 -> S2 | B20: ='Entregas y equipo'!B10 -> Avance funcional 1 (30%) | C20: ="Equipo" -> Equipo | D20: ='Entregas y equipo'!C10 -> 46277 | E20: ='Entregas y equipo'!D10 -> 46290 | F20: ="Hito previsto" -> Hito previsto | G20: =IF(AND(G$7<=$E20,G$7+6>=$E20),"H",IF(AND(G$7<=$E20,G$7+6>=$D20),1,"")) | H20: =IF(AND(H$7<=$E20,H$7+6>=$E20),"H",IF(AND(H$7<=$E20,H$7+6>=$D20),1,"")) | I20: =IF(AND(I$7<=$E20,I$7+6>=$E20),"H",IF(AND(I$7<=$E20,I$7+6>=$D20),1,"")) -> 1 | J20: =IF(AND(J$7<=$E20,J$7+6>=$E20),"H",IF(AND(J$7<=$E20,J$7+6>=$D20),1,"")) -> 1 | K20: =IF(AND(K$7<=$E20,K$7+6>=$E20),"H",IF(AND(K$7<=$E20,K$7+6>=$D20),1,"")) -> H | L20: =IF(AND(L$7<=$E20,L$7+6>=$E20),"H",IF(AND(L$7<=$E20,L$7+6>=$D20),1,"")) | M20: =IF(AND(M$7<=$E20,M$7+6>=$E20),"H",IF(AND(M$7<=$E20,M$7+6>=$D20),1,"")) | N20: =IF(AND(N$7<=$E20,N$7+6>=$E20),"H",IF(AND(N$7<=$E20,N$7+6>=$D20),1,"")) | ... Q20: =IF(AND(Q$7<=$E20,Q$7+6>=$E20),"H",IF(AND(Q$7<=$E20,Q$7+6>=$D20),1,""))
A21: S2-01 | B21: =VLOOKUP($A21,Tareas!$A$8:$P$63,4,FALSE) -> Preparar esqueleto y esquema inicial | C21: =VLOOKUP($A21,Tareas!$A$8:$P$63,5,FALSE) -> Equipo | D21: =VLOOKUP($A21,Tareas!$A$8:$P$63,7,FALSE) -> 46286 | E21: =VLOOKUP($A21,Tareas!$A$8:$P$63,8,FALSE) -> 46286 | F21: =VLOOKUP($A21,Tareas!$A$8:$P$63,11,FALSE) -> Base verificada | G21: =IF(AND(G$7<=$E21,G$7+6>=$D21),1,"") | H21: =IF(AND(H$7<=$E21,H$7+6>=$D21),1,"") | I21: =IF(AND(I$7<=$E21,I$7+6>=$D21),1,"") | J21: =IF(AND(J$7<=$E21,J$7+6>=$D21),1,"") | K21: =IF(AND(K$7<=$E21,K$7+6>=$D21),1,"") -> 1 | L21: =IF(AND(L$7<=$E21,L$7+6>=$D21),1,"") | M21: =IF(AND(M$7<=$E21,M$7+6>=$D21),1,"") | N21: =IF(AND(N$7<=$E21,N$7+6>=$D21),1,"") | ... Q21: =IF(AND(Q$7<=$E21,Q$7+6>=$D21),1,"")
A22: S2-02 | B22: =VLOOKUP($A22,Tareas!$A$8:$P$63,4,FALSE) -> Implementar registro y hash seguro | C22: =VLOOKUP($A22,Tareas!$A$8:$P$63,5,FALSE) -> Andy | D22: =VLOOKUP($A22,Tareas!$A$8:$P$63,7,FALSE) -> 46288 | E22: =VLOOKUP($A22,Tareas!$A$8:$P$63,8,FALSE) -> 46288 | F22: =VLOOKUP($A22,Tareas!$A$8:$P$63,11,FALSE) -> En progreso | G22: =IF(AND(G$7<=$E22,G$7+6>=$D22),1,"") | H22: =IF(AND(H$7<=$E22,H$7+6>=$D22),1,"") | I22: =IF(AND(I$7<=$E22,I$7+6>=$D22),1,"") | J22: =IF(AND(J$7<=$E22,J$7+6>=$D22),1,"") | K22: =IF(AND(K$7<=$E22,K$7+6>=$D22),1,"") -> 1 | L22: =IF(AND(L$7<=$E22,L$7+6>=$D22),1,"") | M22: =IF(AND(M$7<=$E22,M$7+6>=$D22),1,"") | N22: =IF(AND(N$7<=$E22,N$7+6>=$D22),1,"") | ... Q22: =IF(AND(Q$7<=$E22,Q$7+6>=$D22),1,"")
A23: S2-03 | B23: =VLOOKUP($A23,Tareas!$A$8:$P$63,4,FALSE) -> Implementar login, JWT y protección | C23: =VLOOKUP($A23,Tareas!$A$8:$P$63,5,FALSE) -> Andy | D23: =VLOOKUP($A23,Tareas!$A$8:$P$63,7,FALSE) -> 46289 | E23: =VLOOKUP($A23,Tareas!$A$8:$P$63,8,FALSE) -> 46289 | F23: =VLOOKUP($A23,Tareas!$A$8:$P$63,11,FALSE) -> En progreso | G23: =IF(AND(G$7<=$E23,G$7+6>=$D23),1,"") | H23: =IF(AND(H$7<=$E23,H$7+6>=$D23),1,"") | I23: =IF(AND(I$7<=$E23,I$7+6>=$D23),1,"") | J23: =IF(AND(J$7<=$E23,J$7+6>=$D23),1,"") | K23: =IF(AND(K$7<=$E23,K$7+6>=$D23),1,"") -> 1 | L23: =IF(AND(L$7<=$E23,L$7+6>=$D23),1,"") | M23: =IF(AND(M$7<=$E23,M$7+6>=$D23),1,"") | N23: =IF(AND(N$7<=$E23,N$7+6>=$D23),1,"") | ... Q23: =IF(AND(Q$7<=$E23,Q$7+6>=$D23),1,"")
A24: S2-04 | B24: =VLOOKUP($A24,Tareas!$A$8:$P$63,4,FALSE) -> Revisar catálogo y contrato de Free | C24: =VLOOKUP($A24,Tareas!$A$8:$P$63,5,FALSE) -> Elden | D24: =VLOOKUP($A24,Tareas!$A$8:$P$63,7,FALSE) -> 46288 | E24: =VLOOKUP($A24,Tareas!$A$8:$P$63,8,FALSE) -> 46288 | F24: =VLOOKUP($A24,Tareas!$A$8:$P$63,11,FALSE) -> Planificada | G24: =IF(AND(G$7<=$E24,G$7+6>=$D24),1,"") | H24: =IF(AND(H$7<=$E24,H$7+6>=$D24),1,"") | I24: =IF(AND(I$7<=$E24,I$7+6>=$D24),1,"") | J24: =IF(AND(J$7<=$E24,J$7+6>=$D24),1,"") | K24: =IF(AND(K$7<=$E24,K$7+6>=$D24),1,"") -> 1 | L24: =IF(AND(L$7<=$E24,L$7+6>=$D24),1,"") | M24: =IF(AND(M$7<=$E24,M$7+6>=$D24),1,"") | N24: =IF(AND(N$7<=$E24,N$7+6>=$D24),1,"") | ... Q24: =IF(AND(Q$7<=$E24,Q$7+6>=$D24),1,"")
A25: S2-05 | B25: =VLOOKUP($A25,Tareas!$A$8:$P$63,4,FALSE) -> Asignar Free al registrar | C25: =VLOOKUP($A25,Tareas!$A$8:$P$63,5,FALSE) -> Elden | D25: =VLOOKUP($A25,Tareas!$A$8:$P$63,7,FALSE) -> 46289 | E25: =VLOOKUP($A25,Tareas!$A$8:$P$63,8,FALSE) -> 46289 | F25: =VLOOKUP($A25,Tareas!$A$8:$P$63,11,FALSE) -> Hecha | G25: =IF(AND(G$7<=$E25,G$7+6>=$D25),1,"") | H25: =IF(AND(H$7<=$E25,H$7+6>=$D25),1,"") | I25: =IF(AND(I$7<=$E25,I$7+6>=$D25),1,"") | J25: =IF(AND(J$7<=$E25,J$7+6>=$D25),1,"") | K25: =IF(AND(K$7<=$E25,K$7+6>=$D25),1,"") -> 1 | L25: =IF(AND(L$7<=$E25,L$7+6>=$D25),1,"") | M25: =IF(AND(M$7<=$E25,M$7+6>=$D25),1,"") | N25: =IF(AND(N$7<=$E25,N$7+6>=$D25),1,"") | ... Q25: =IF(AND(Q$7<=$E25,Q$7+6>=$D25),1,"")
A26: S2-06 | B26: =VLOOKUP($A26,Tareas!$A$8:$P$63,4,FALSE) -> Aplicar capacidad y límites diarios | C26: =VLOOKUP($A26,Tareas!$A$8:$P$63,5,FALSE) -> Elden | D26: =VLOOKUP($A26,Tareas!$A$8:$P$63,7,FALSE) -> 46289 | E26: =VLOOKUP($A26,Tareas!$A$8:$P$63,8,FALSE) -> 46289 | F26: =VLOOKUP($A26,Tareas!$A$8:$P$63,11,FALSE) -> Pendiente | G26: =IF(AND(G$7<=$E26,G$7+6>=$D26),1,"") | H26: =IF(AND(H$7<=$E26,H$7+6>=$D26),1,"") | I26: =IF(AND(I$7<=$E26,I$7+6>=$D26),1,"") | J26: =IF(AND(J$7<=$E26,J$7+6>=$D26),1,"") | K26: =IF(AND(K$7<=$E26,K$7+6>=$D26),1,"") -> 1 | L26: =IF(AND(L$7<=$E26,L$7+6>=$D26),1,"") | M26: =IF(AND(M$7<=$E26,M$7+6>=$D26),1,"") | N26: =IF(AND(N$7<=$E26,N$7+6>=$D26),1,"") | ... Q26: =IF(AND(Q$7<=$E26,Q$7+6>=$D26),1,"")
A27: S2-07 | B27: =VLOOKUP($A27,Tareas!$A$8:$P$63,4,FALSE) -> Validar archivo y calcular SHA-256 | C27: =VLOOKUP($A27,Tareas!$A$8:$P$63,5,FALSE) -> Geovanny | D27: =VLOOKUP($A27,Tareas!$A$8:$P$63,7,FALSE) -> 46288 | E27: =VLOOKUP($A27,Tareas!$A$8:$P$63,8,FALSE) -> 46288 | F27: =VLOOKUP($A27,Tareas!$A$8:$P$63,11,FALSE) -> Pendiente | G27: =IF(AND(G$7<=$E27,G$7+6>=$D27),1,"") | H27: =IF(AND(H$7<=$E27,H$7+6>=$D27),1,"") | I27: =IF(AND(I$7<=$E27,I$7+6>=$D27),1,"") | J27: =IF(AND(J$7<=$E27,J$7+6>=$D27),1,"") | K27: =IF(AND(K$7<=$E27,K$7+6>=$D27),1,"") -> 1 | L27: =IF(AND(L$7<=$E27,L$7+6>=$D27),1,"") | M27: =IF(AND(M$7<=$E27,M$7+6>=$D27),1,"") | N27: =IF(AND(N$7<=$E27,N$7+6>=$D27),1,"") | ... Q27: =IF(AND(Q$7<=$E27,Q$7+6>=$D27),1,"")
A28: S2-08 | B28: =VLOOKUP($A28,Tareas!$A$8:$P$63,4,FALSE) -> Convertir a WebP y limpiar temporales | C28: =VLOOKUP($A28,Tareas!$A$8:$P$63,5,FALSE) -> Geovanny | D28: =VLOOKUP($A28,Tareas!$A$8:$P$63,7,FALSE) -> 46289 | E28: =VLOOKUP($A28,Tareas!$A$8:$P$63,8,FALSE) -> 46289 | F28: =VLOOKUP($A28,Tareas!$A$8:$P$63,11,FALSE) -> Pendiente | G28: =IF(AND(G$7<=$E28,G$7+6>=$D28),1,"") | H28: =IF(AND(H$7<=$E28,H$7+6>=$D28),1,"") | I28: =IF(AND(I$7<=$E28,I$7+6>=$D28),1,"") | J28: =IF(AND(J$7<=$E28,J$7+6>=$D28),1,"") | K28: =IF(AND(K$7<=$E28,K$7+6>=$D28),1,"") -> 1 | L28: =IF(AND(L$7<=$E28,L$7+6>=$D28),1,"") | M28: =IF(AND(M$7<=$E28,M$7+6>=$D28),1,"") | N28: =IF(AND(N$7<=$E28,N$7+6>=$D28),1,"") | ... Q28: =IF(AND(Q$7<=$E28,Q$7+6>=$D28),1,"")
A29: S2-09 | B29: =VLOOKUP($A29,Tareas!$A$8:$P$63,4,FALSE) -> Integrar carga y deduplicación global | C29: =VLOOKUP($A29,Tareas!$A$8:$P$63,5,FALSE) -> Geovanny | D29: =VLOOKUP($A29,Tareas!$A$8:$P$63,7,FALSE) -> 46289 | E29: =VLOOKUP($A29,Tareas!$A$8:$P$63,8,FALSE) -> 46289 | F29: =VLOOKUP($A29,Tareas!$A$8:$P$63,11,FALSE) -> Pendiente | G29: =IF(AND(G$7<=$E29,G$7+6>=$D29),1,"") | H29: =IF(AND(H$7<=$E29,H$7+6>=$D29),1,"") | I29: =IF(AND(I$7<=$E29,I$7+6>=$D29),1,"") | J29: =IF(AND(J$7<=$E29,J$7+6>=$D29),1,"") | K29: =IF(AND(K$7<=$E29,K$7+6>=$D29),1,"") -> 1 | L29: =IF(AND(L$7<=$E29,L$7+6>=$D29),1,"") | M29: =IF(AND(M$7<=$E29,M$7+6>=$D29),1,"") | N29: =IF(AND(N$7<=$E29,N$7+6>=$D29),1,"") | ... Q29: =IF(AND(Q$7<=$E29,Q$7+6>=$D29),1,"")
A30: S2-10 | B30: =VLOOKUP($A30,Tareas!$A$8:$P$63,4,FALSE) -> Proteger galería y descarga WebP | C30: =VLOOKUP($A30,Tareas!$A$8:$P$63,5,FALSE) -> Geovanny | D30: =VLOOKUP($A30,Tareas!$A$8:$P$63,7,FALSE) -> 46290 | E30: =VLOOKUP($A30,Tareas!$A$8:$P$63,8,FALSE) -> 46290 | F30: =VLOOKUP($A30,Tareas!$A$8:$P$63,11,FALSE) -> Pendiente | G30: =IF(AND(G$7<=$E30,G$7+6>=$D30),1,"") | H30: =IF(AND(H$7<=$E30,H$7+6>=$D30),1,"") | I30: =IF(AND(I$7<=$E30,I$7+6>=$D30),1,"") | J30: =IF(AND(J$7<=$E30,J$7+6>=$D30),1,"") | K30: =IF(AND(K$7<=$E30,K$7+6>=$D30),1,"") -> 1 | L30: =IF(AND(L$7<=$E30,L$7+6>=$D30),1,"") | M30: =IF(AND(M$7<=$E30,M$7+6>=$D30),1,"") | N30: =IF(AND(N$7<=$E30,N$7+6>=$D30),1,"") | ... Q30: =IF(AND(Q$7<=$E30,Q$7+6>=$D30),1,"")
A31: S2-11 | B31: =VLOOKUP($A31,Tareas!$A$8:$P$63,4,FALSE) -> Preparar formularios y estados de interfaz | C31: =VLOOKUP($A31,Tareas!$A$8:$P$63,5,FALSE) -> Diego | D31: =VLOOKUP($A31,Tareas!$A$8:$P$63,7,FALSE) -> 46288 | E31: =VLOOKUP($A31,Tareas!$A$8:$P$63,8,FALSE) -> 46288 | F31: =VLOOKUP($A31,Tareas!$A$8:$P$63,11,FALSE) -> Pendiente | G31: =IF(AND(G$7<=$E31,G$7+6>=$D31),1,"") | H31: =IF(AND(H$7<=$E31,H$7+6>=$D31),1,"") | I31: =IF(AND(I$7<=$E31,I$7+6>=$D31),1,"") | J31: =IF(AND(J$7<=$E31,J$7+6>=$D31),1,"") | K31: =IF(AND(K$7<=$E31,K$7+6>=$D31),1,"") -> 1 | L31: =IF(AND(L$7<=$E31,L$7+6>=$D31),1,"") | M31: =IF(AND(M$7<=$E31,M$7+6>=$D31),1,"") | N31: =IF(AND(N$7<=$E31,N$7+6>=$D31),1,"") | ... Q31: =IF(AND(Q$7<=$E31,Q$7+6>=$D31),1,"")
A32: S2-12 | B32: =VLOOKUP($A32,Tareas!$A$8:$P$63,4,FALSE) -> Conectar acceso, Free, carga y galería | C32: =VLOOKUP($A32,Tareas!$A$8:$P$63,5,FALSE) -> Diego | D32: =VLOOKUP($A32,Tareas!$A$8:$P$63,7,FALSE) -> 46289 | E32: =VLOOKUP($A32,Tareas!$A$8:$P$63,8,FALSE) -> 46290 | F32: =VLOOKUP($A32,Tareas!$A$8:$P$63,11,FALSE) -> Pendiente | G32: =IF(AND(G$7<=$E32,G$7+6>=$D32),1,"") | H32: =IF(AND(H$7<=$E32,H$7+6>=$D32),1,"") | I32: =IF(AND(I$7<=$E32,I$7+6>=$D32),1,"") | J32: =IF(AND(J$7<=$E32,J$7+6>=$D32),1,"") | K32: =IF(AND(K$7<=$E32,K$7+6>=$D32),1,"") -> 1 | L32: =IF(AND(L$7<=$E32,L$7+6>=$D32),1,"") | M32: =IF(AND(M$7<=$E32,M$7+6>=$D32),1,"") | N32: =IF(AND(N$7<=$E32,N$7+6>=$D32),1,"") | ... Q32: =IF(AND(Q$7<=$E32,Q$7+6>=$D32),1,"")
... A36: S2-16 | B36: =VLOOKUP($A36,Tareas!$A$8:$P$63,4,FALSE) -> Corregir, revisar PR y presentar 30% | C36: =VLOOKUP($A36,Tareas!$A$8:$P$63,5,FALSE) -> Equipo | D36: =VLOOKUP($A36,Tareas!$A$8:$P$63,7,FALSE) -> 46290 | E36: =VLOOKUP($A36,Tareas!$A$8:$P$63,8,FALSE) -> 46290 | F36: =VLOOKUP($A36,Tareas!$A$8:$P$63,11,FALSE) -> Pendiente | G36: =IF(AND(G$7<=$E36,G$7+6>=$D36),1,"") | H36: =IF(AND(H$7<=$E36,H$7+6>=$D36),1,"") | I36: =IF(AND(I$7<=$E36,I$7+6>=$D36),1,"") | J36: =IF(AND(J$7<=$E36,J$7+6>=$D36),1,"") | K36: =IF(AND(K$7<=$E36,K$7+6>=$D36),1,"") -> 1 | L36: =IF(AND(L$7<=$E36,L$7+6>=$D36),1,"") | M36: =IF(AND(M$7<=$E36,M$7+6>=$D36),1,"") | N36: =IF(AND(N$7<=$E36,N$7+6>=$D36),1,"") | ... Q36: =IF(AND(Q$7<=$E36,Q$7+6>=$D36),1,"")
A37: ='Entregas y equipo'!A11 -> S3 | B37: ='Entregas y equipo'!B11 -> Avance funcional 2 (50%) | C37: ="Equipo" -> Equipo | D37: ='Entregas y equipo'!C11 -> 46291 | E37: ='Entregas y equipo'!D11 -> 46304 | F37: ="Hito previsto" -> Hito previsto | G37: =IF(AND(G$7<=$E37,G$7+6>=$E37),"H",IF(AND(G$7<=$E37,G$7+6>=$D37),1,"")) | H37: =IF(AND(H$7<=$E37,H$7+6>=$E37),"H",IF(AND(H$7<=$E37,H$7+6>=$D37),1,"")) | I37: =IF(AND(I$7<=$E37,I$7+6>=$E37),"H",IF(AND(I$7<=$E37,I$7+6>=$D37),1,"")) | J37: =IF(AND(J$7<=$E37,J$7+6>=$E37),"H",IF(AND(J$7<=$E37,J$7+6>=$D37),1,"")) | K37: =IF(AND(K$7<=$E37,K$7+6>=$E37),"H",IF(AND(K$7<=$E37,K$7+6>=$D37),1,"")) -> 1 | L37: =IF(AND(L$7<=$E37,L$7+6>=$E37),"H",IF(AND(L$7<=$E37,L$7+6>=$D37),1,"")) -> 1 | M37: =IF(AND(M$7<=$E37,M$7+6>=$E37),"H",IF(AND(M$7<=$E37,M$7+6>=$D37),1,"")) -> H | N37: =IF(AND(N$7<=$E37,N$7+6>=$E37),"H",IF(AND(N$7<=$E37,N$7+6>=$D37),1,"")) | ... Q37: =IF(AND(Q$7<=$E37,Q$7+6>=$E37),"H",IF(AND(Q$7<=$E37,Q$7+6>=$D37),1,""))
A38: S3-01 | B38: =VLOOKUP($A38,Tareas!$A$8:$P$63,4,FALSE) -> Implementar verificación de correo | C38: =VLOOKUP($A38,Tareas!$A$8:$P$63,5,FALSE) -> Andy | D38: =VLOOKUP($A38,Tareas!$A$8:$P$63,7,FALSE) -> 46293 | E38: =VLOOKUP($A38,Tareas!$A$8:$P$63,8,FALSE) -> 46295 | F38: =VLOOKUP($A38,Tareas!$A$8:$P$63,11,FALSE) -> Planificada | G38: =IF(AND(G$7<=$E38,G$7+6>=$D38),1,"") | H38: =IF(AND(H$7<=$E38,H$7+6>=$D38),1,"") | I38: =IF(AND(I$7<=$E38,I$7+6>=$D38),1,"") | J38: =IF(AND(J$7<=$E38,J$7+6>=$D38),1,"") | K38: =IF(AND(K$7<=$E38,K$7+6>=$D38),1,"") | L38: =IF(AND(L$7<=$E38,L$7+6>=$D38),1,"") -> 1 | M38: =IF(AND(M$7<=$E38,M$7+6>=$D38),1,"") | N38: =IF(AND(N$7<=$E38,N$7+6>=$D38),1,"") | ... Q38: =IF(AND(Q$7<=$E38,Q$7+6>=$D38),1,"")
A39: S3-02 | B39: =VLOOKUP($A39,Tareas!$A$8:$P$63,4,FALSE) -> Recuperar y cambiar contraseña | C39: =VLOOKUP($A39,Tareas!$A$8:$P$63,5,FALSE) -> Andy | D39: =VLOOKUP($A39,Tareas!$A$8:$P$63,7,FALSE) -> 46296 | E39: =VLOOKUP($A39,Tareas!$A$8:$P$63,8,FALSE) -> 46300 | F39: =VLOOKUP($A39,Tareas!$A$8:$P$63,11,FALSE) -> Planificada | G39: =IF(AND(G$7<=$E39,G$7+6>=$D39),1,"") | H39: =IF(AND(H$7<=$E39,H$7+6>=$D39),1,"") | I39: =IF(AND(I$7<=$E39,I$7+6>=$D39),1,"") | J39: =IF(AND(J$7<=$E39,J$7+6>=$D39),1,"") | K39: =IF(AND(K$7<=$E39,K$7+6>=$D39),1,"") | L39: =IF(AND(L$7<=$E39,L$7+6>=$D39),1,"") -> 1 | M39: =IF(AND(M$7<=$E39,M$7+6>=$D39),1,"") -> 1 | N39: =IF(AND(N$7<=$E39,N$7+6>=$D39),1,"") | ... Q39: =IF(AND(Q$7<=$E39,Q$7+6>=$D39),1,"")
A40: S3-03 | B40: =VLOOKUP($A40,Tareas!$A$8:$P$63,4,FALSE) -> Completar sesiones revocables y logout | C40: =VLOOKUP($A40,Tareas!$A$8:$P$63,5,FALSE) -> Andy | D40: =VLOOKUP($A40,Tareas!$A$8:$P$63,7,FALSE) -> 46301 | E40: =VLOOKUP($A40,Tareas!$A$8:$P$63,8,FALSE) -> 46302 | F40: =VLOOKUP($A40,Tareas!$A$8:$P$63,11,FALSE) -> Planificada | G40: =IF(AND(G$7<=$E40,G$7+6>=$D40),1,"") | H40: =IF(AND(H$7<=$E40,H$7+6>=$D40),1,"") | I40: =IF(AND(I$7<=$E40,I$7+6>=$D40),1,"") | J40: =IF(AND(J$7<=$E40,J$7+6>=$D40),1,"") | K40: =IF(AND(K$7<=$E40,K$7+6>=$D40),1,"") | L40: =IF(AND(L$7<=$E40,L$7+6>=$D40),1,"") | M40: =IF(AND(M$7<=$E40,M$7+6>=$D40),1,"") -> 1 | N40: =IF(AND(N$7<=$E40,N$7+6>=$D40),1,"") | ... Q40: =IF(AND(Q$7<=$E40,Q$7+6>=$D40),1,"")
A41: S3-04 | B41: =VLOOKUP($A41,Tareas!$A$8:$P$63,4,FALSE) -> Implementar Redis, BullMQ y worker Sharp | C41: =VLOOKUP($A41,Tareas!$A$8:$P$63,5,FALSE) -> Geovanny | D41: =VLOOKUP($A41,Tareas!$A$8:$P$63,7,FALSE) -> 46293 | E41: =VLOOKUP($A41,Tareas!$A$8:$P$63,8,FALSE) -> 46296 | F41: =VLOOKUP($A41,Tareas!$A$8:$P$63,11,FALSE) -> Planificada | G41: =IF(AND(G$7<=$E41,G$7+6>=$D41),1,"") | H41: =IF(AND(H$7<=$E41,H$7+6>=$D41),1,"") | I41: =IF(AND(I$7<=$E41,I$7+6>=$D41),1,"") | J41: =IF(AND(J$7<=$E41,J$7+6>=$D41),1,"") | K41: =IF(AND(K$7<=$E41,K$7+6>=$D41),1,"") | L41: =IF(AND(L$7<=$E41,L$7+6>=$D41),1,"") -> 1 | M41: =IF(AND(M$7<=$E41,M$7+6>=$D41),1,"") | N41: =IF(AND(N$7<=$E41,N$7+6>=$D41),1,"") | ... Q41: =IF(AND(Q$7<=$E41,Q$7+6>=$D41),1,"")
A42: S3-05 | B42: =VLOOKUP($A42,Tareas!$A$8:$P$63,4,FALSE) -> Añadir reintentos y recuperación de trabajos | C42: =VLOOKUP($A42,Tareas!$A$8:$P$63,5,FALSE) -> Geovanny | D42: =VLOOKUP($A42,Tareas!$A$8:$P$63,7,FALSE) -> 46297 | E42: =VLOOKUP($A42,Tareas!$A$8:$P$63,8,FALSE) -> 46300 | F42: =VLOOKUP($A42,Tareas!$A$8:$P$63,11,FALSE) -> Planificada | G42: =IF(AND(G$7<=$E42,G$7+6>=$D42),1,"") | H42: =IF(AND(H$7<=$E42,H$7+6>=$D42),1,"") | I42: =IF(AND(I$7<=$E42,I$7+6>=$D42),1,"") | J42: =IF(AND(J$7<=$E42,J$7+6>=$D42),1,"") | K42: =IF(AND(K$7<=$E42,K$7+6>=$D42),1,"") | L42: =IF(AND(L$7<=$E42,L$7+6>=$D42),1,"") -> 1 | M42: =IF(AND(M$7<=$E42,M$7+6>=$D42),1,"") -> 1 | N42: =IF(AND(N$7<=$E42,N$7+6>=$D42),1,"") | ... Q42: =IF(AND(Q$7<=$E42,Q$7+6>=$D42),1,"")
A43: S3-06 | B43: =VLOOKUP($A43,Tareas!$A$8:$P$63,4,FALSE) -> Implementar borrado con referencias | C43: =VLOOKUP($A43,Tareas!$A$8:$P$63,5,FALSE) -> Geovanny | D43: =VLOOKUP($A43,Tareas!$A$8:$P$63,7,FALSE) -> 46301 | E43: =VLOOKUP($A43,Tareas!$A$8:$P$63,8,FALSE) -> 46301 | F43: =VLOOKUP($A43,Tareas!$A$8:$P$63,11,FALSE) -> Planificada | G43: =IF(AND(G$7<=$E43,G$7+6>=$D43),1,"") | H43: =IF(AND(H$7<=$E43,H$7+6>=$D43),1,"") | I43: =IF(AND(I$7<=$E43,I$7+6>=$D43),1,"") | J43: =IF(AND(J$7<=$E43,J$7+6>=$D43),1,"") | K43: =IF(AND(K$7<=$E43,K$7+6>=$D43),1,"") | L43: =IF(AND(L$7<=$E43,L$7+6>=$D43),1,"") | M43: =IF(AND(M$7<=$E43,M$7+6>=$D43),1,"") -> 1 | N43: =IF(AND(N$7<=$E43,N$7+6>=$D43),1,"") | ... Q43: =IF(AND(Q$7<=$E43,Q$7+6>=$D43),1,"")
A44: S3-07 | B44: =VLOOKUP($A44,Tareas!$A$8:$P$63,4,FALSE) -> Crear álbumes y mover imágenes | C44: =VLOOKUP($A44,Tareas!$A$8:$P$63,5,FALSE) -> Geovanny | D44: =VLOOKUP($A44,Tareas!$A$8:$P$63,7,FALSE) -> 46302 | E44: =VLOOKUP($A44,Tareas!$A$8:$P$63,8,FALSE) -> 46302 | F44: =VLOOKUP($A44,Tareas!$A$8:$P$63,11,FALSE) -> Planificada | G44: =IF(AND(G$7<=$E44,G$7+6>=$D44),1,"") | H44: =IF(AND(H$7<=$E44,H$7+6>=$D44),1,"") | I44: =IF(AND(I$7<=$E44,I$7+6>=$D44),1,"") | J44: =IF(AND(J$7<=$E44,J$7+6>=$D44),1,"") | K44: =IF(AND(K$7<=$E44,K$7+6>=$D44),1,"") | L44: =IF(AND(L$7<=$E44,L$7+6>=$D44),1,"") | M44: =IF(AND(M$7<=$E44,M$7+6>=$D44),1,"") -> 1 | N44: =IF(AND(N$7<=$E44,N$7+6>=$D44),1,"") | ... Q44: =IF(AND(Q$7<=$E44,Q$7+6>=$D44),1,"")
...

Sheet Detalle 30%
A2: SmartStorage — Cierre del avance del 30%
A3: Vista diaria del sprint 2: 12–25 de septiembre. La base se verificó; las funciones figuran pendientes en los documentos.
A4: Cierre propuesto del 23 al 25/09. Rojo en la cabecera: día de entrega. Las fechas dependen de la disponibilidad del equipo.
A5: Orden: registro y Free → autenticación y límites → carga WebP → pantallas y ahorro → pruebas con dos cuentas.
A6: Cambiar estado y adjuntar evidencia en Tareas; completar el recorrido de aceptación antes de declarar alcanzado el 30%.
A7: ID | B7: Actividad | C7: Responsable | D7: Inicio | E7: Fin | F7: Estado reportado | G7: 46277 | H7: 46278 | I7: 46279 | J7: 46280 | K7: 46281 | L7: 46282 | M7: 46283 | N7: 46284 | O7: 46285 | P7: 46286 | Q7: 46287 | R7: 46288 | S7: 46289 | T7: 46290
A8: S2-01 | B8: =VLOOKUP($A8,Tareas!$A$8:$P$63,4,FALSE) -> Preparar esqueleto y esquema inicial | C8: =VLOOKUP($A8,Tareas!$A$8:$P$63,5,FALSE) -> Equipo | D8: =VLOOKUP($A8,Tareas!$A$8:$P$63,7,FALSE) -> 46286 | E8: =VLOOKUP($A8,Tareas!$A$8:$P$63,8,FALSE) -> 46286 | F8: =VLOOKUP($A8,Tareas!$A$8:$P$63,11,FALSE) -> Base verificada | G8: =IF(AND(G$7>=$D8,G$7<=$E8),1,"") | H8: =IF(AND(H$7>=$D8,H$7<=$E8),1,"") | I8: =IF(AND(I$7>=$D8,I$7<=$E8),1,"") | J8: =IF(AND(J$7>=$D8,J$7<=$E8),1,"") | K8: =IF(AND(K$7>=$D8,K$7<=$E8),1,"") | L8: =IF(AND(L$7>=$D8,L$7<=$E8),1,"") | M8: =IF(AND(M$7>=$D8,M$7<=$E8),1,"") | N8: =IF(AND(N$7>=$D8,N$7<=$E8),1,"") | ... T8: =IF(AND(T$7>=$D8,T$7<=$E8),1,"")
A9: S2-02 | B9: =VLOOKUP($A9,Tareas!$A$8:$P$63,4,FALSE) -> Implementar registro y hash seguro | C9: =VLOOKUP($A9,Tareas!$A$8:$P$63,5,FALSE) -> Andy | D9: =VLOOKUP($A9,Tareas!$A$8:$P$63,7,FALSE) -> 46288 | E9: =VLOOKUP($A9,Tareas!$A$8:$P$63,8,FALSE) -> 46288 | F9: =VLOOKUP($A9,Tareas!$A$8:$P$63,11,FALSE) -> En progreso | G9: =IF(AND(G$7>=$D9,G$7<=$E9),1,"") | H9: =IF(AND(H$7>=$D9,H$7<=$E9),1,"") | I9: =IF(AND(I$7>=$D9,I$7<=$E9),1,"") | J9: =IF(AND(J$7>=$D9,J$7<=$E9),1,"") | K9: =IF(AND(K$7>=$D9,K$7<=$E9),1,"") | L9: =IF(AND(L$7>=$D9,L$7<=$E9),1,"") | M9: =IF(AND(M$7>=$D9,M$7<=$E9),1,"") | N9: =IF(AND(N$7>=$D9,N$7<=$E9),1,"") | ... T9: =IF(AND(T$7>=$D9,T$7<=$E9),1,"")
A10: S2-03 | B10: =VLOOKUP($A10,Tareas!$A$8:$P$63,4,FALSE) -> Implementar login, JWT y protección | C10: =VLOOKUP($A10,Tareas!$A$8:$P$63,5,FALSE) -> Andy | D10: =VLOOKUP($A10,Tareas!$A$8:$P$63,7,FALSE) -> 46289 | E10: =VLOOKUP($A10,Tareas!$A$8:$P$63,8,FALSE) -> 46289 | F10: =VLOOKUP($A10,Tareas!$A$8:$P$63,11,FALSE) -> En progreso | G10: =IF(AND(G$7>=$D10,G$7<=$E10),1,"") | H10: =IF(AND(H$7>=$D10,H$7<=$E10),1,"") | I10: =IF(AND(I$7>=$D10,I$7<=$E10),1,"") | J10: =IF(AND(J$7>=$D10,J$7<=$E10),1,"") | K10: =IF(AND(K$7>=$D10,K$7<=$E10),1,"") | L10: =IF(AND(L$7>=$D10,L$7<=$E10),1,"") | M10: =IF(AND(M$7>=$D10,M$7<=$E10),1,"") | N10: =IF(AND(N$7>=$D10,N$7<=$E10),1,"") | ... T10: =IF(AND(T$7>=$D10,T$7<=$E10),1,"")
A11: S2-04 | B11: =VLOOKUP($A11,Tareas!$A$8:$P$63,4,FALSE) -> Revisar catálogo y contrato de Free | C11: =VLOOKUP($A11,Tareas!$A$8:$P$63,5,FALSE) -> Elden | D11: =VLOOKUP($A11,Tareas!$A$8:$P$63,7,FALSE) -> 46288 | E11: =VLOOKUP($A11,Tareas!$A$8:$P$63,8,FALSE) -> 46288 | F11: =VLOOKUP($A11,Tareas!$A$8:$P$63,11,FALSE) -> Planificada | G11: =IF(AND(G$7>=$D11,G$7<=$E11),1,"") | H11: =IF(AND(H$7>=$D11,H$7<=$E11),1,"") | I11: =IF(AND(I$7>=$D11,I$7<=$E11),1,"") | J11: =IF(AND(J$7>=$D11,J$7<=$E11),1,"") | K11: =IF(AND(K$7>=$D11,K$7<=$E11),1,"") | L11: =IF(AND(L$7>=$D11,L$7<=$E11),1,"") | M11: =IF(AND(M$7>=$D11,M$7<=$E11),1,"") | N11: =IF(AND(N$7>=$D11,N$7<=$E11),1,"") | ... T11: =IF(AND(T$7>=$D11,T$7<=$E11),1,"")
A12: S2-05 | B12: =VLOOKUP($A12,Tareas!$A$8:$P$63,4,FALSE) -> Asignar Free al registrar | C12: =VLOOKUP($A12,Tareas!$A$8:$P$63,5,FALSE) -> Elden | D12: =VLOOKUP($A12,Tareas!$A$8:$P$63,7,FALSE) -> 46289 | E12: =VLOOKUP($A12,Tareas!$A$8:$P$63,8,FALSE) -> 46289 | F12: =VLOOKUP($A12,Tareas!$A$8:$P$63,11,FALSE) -> Hecha | G12: =IF(AND(G$7>=$D12,G$7<=$E12),1,"") | H12: =IF(AND(H$7>=$D12,H$7<=$E12),1,"") | I12: =IF(AND(I$7>=$D12,I$7<=$E12),1,"") | J12: =IF(AND(J$7>=$D12,J$7<=$E12),1,"") | K12: =IF(AND(K$7>=$D12,K$7<=$E12),1,"") | L12: =IF(AND(L$7>=$D12,L$7<=$E12),1,"") | M12: =IF(AND(M$7>=$D12,M$7<=$E12),1,"") | N12: =IF(AND(N$7>=$D12,N$7<=$E12),1,"") | ... T12: =IF(AND(T$7>=$D12,T$7<=$E12),1,"")
A13: S2-06 | B13: =VLOOKUP($A13,Tareas!$A$8:$P$63,4,FALSE) -> Aplicar capacidad y límites diarios | C13: =VLOOKUP($A13,Tareas!$A$8:$P$63,5,FALSE) -> Elden | D13: =VLOOKUP($A13,Tareas!$A$8:$P$63,7,FALSE) -> 46289 | E13: =VLOOKUP($A13,Tareas!$A$8:$P$63,8,FALSE) -> 46289 | F13: =VLOOKUP($A13,Tareas!$A$8:$P$63,11,FALSE) -> Pendiente | G13: =IF(AND(G$7>=$D13,G$7<=$E13),1,"") | H13: =IF(AND(H$7>=$D13,H$7<=$E13),1,"") | I13: =IF(AND(I$7>=$D13,I$7<=$E13),1,"") | J13: =IF(AND(J$7>=$D13,J$7<=$E13),1,"") | K13: =IF(AND(K$7>=$D13,K$7<=$E13),1,"") | L13: =IF(AND(L$7>=$D13,L$7<=$E13),1,"") | M13: =IF(AND(M$7>=$D13,M$7<=$E13),1,"") | N13: =IF(AND(N$7>=$D13,N$7<=$E13),1,"") | ... T13: =IF(AND(T$7>=$D13,T$7<=$E13),1,"")
A14: S2-07 | B14: =VLOOKUP($A14,Tareas!$A$8:$P$63,4,FALSE) -> Validar archivo y calcular SHA-256 | C14: =VLOOKUP($A14,Tareas!$A$8:$P$63,5,FALSE) -> Geovanny | D14: =VLOOKUP($A14,Tareas!$A$8:$P$63,7,FALSE) -> 46288 | E14: =VLOOKUP($A14,Tareas!$A$8:$P$63,8,FALSE) -> 46288 | F14: =VLOOKUP($A14,Tareas!$A$8:$P$63,11,FALSE) -> Pendiente | G14: =IF(AND(G$7>=$D14,G$7<=$E14),1,"") | H14: =IF(AND(H$7>=$D14,H$7<=$E14),1,"") | I14: =IF(AND(I$7>=$D14,I$7<=$E14),1,"") | J14: =IF(AND(J$7>=$D14,J$7<=$E14),1,"") | K14: =IF(AND(K$7>=$D14,K$7<=$E14),1,"") | L14: =IF(AND(L$7>=$D14,L$7<=$E14),1,"") | M14: =IF(AND(M$7>=$D14,M$7<=$E14),1,"") | N14: =IF(AND(N$7>=$D14,N$7<=$E14),1,"") | ... T14: =IF(AND(T$7>=$D14,T$7<=$E14),1,"")
A15: S2-08 | B15: =VLOOKUP($A15,Tareas!$A$8:$P$63,4,FALSE) -> Convertir a WebP y limpiar temporales | C15: =VLOOKUP($A15,Tareas!$A$8:$P$63,5,FALSE) -> Geovanny | D15: =VLOOKUP($A15,Tareas!$A$8:$P$63,7,FALSE) -> 46289 | E15: =VLOOKUP($A15,Tareas!$A$8:$P$63,8,FALSE) -> 46289 | F15: =VLOOKUP($A15,Tareas!$A$8:$P$63,11,FALSE) -> Pendiente | G15: =IF(AND(G$7>=$D15,G$7<=$E15),1,"") | H15: =IF(AND(H$7>=$D15,H$7<=$E15),1,"") | I15: =IF(AND(I$7>=$D15,I$7<=$E15),1,"") | J15: =IF(AND(J$7>=$D15,J$7<=$E15),1,"") | K15: =IF(AND(K$7>=$D15,K$7<=$E15),1,"") | L15: =IF(AND(L$7>=$D15,L$7<=$E15),1,"") | M15: =IF(AND(M$7>=$D15,M$7<=$E15),1,"") | N15: =IF(AND(N$7>=$D15,N$7<=$E15),1,"") | ... T15: =IF(AND(T$7>=$D15,T$7<=$E15),1,"")
A16: S2-09 | B16: =VLOOKUP($A16,Tareas!$A$8:$P$63,4,FALSE) -> Integrar carga y deduplicación global | C16: =VLOOKUP($A16,Tareas!$A$8:$P$63,5,FALSE) -> Geovanny | D16: =VLOOKUP($A16,Tareas!$A$8:$P$63,7,FALSE) -> 46289 | E16: =VLOOKUP($A16,Tareas!$A$8:$P$63,8,FALSE) -> 46289 | F16: =VLOOKUP($A16,Tareas!$A$8:$P$63,11,FALSE) -> Pendiente | G16: =IF(AND(G$7>=$D16,G$7<=$E16),1,"") | H16: =IF(AND(H$7>=$D16,H$7<=$E16),1,"") | I16: =IF(AND(I$7>=$D16,I$7<=$E16),1,"") | J16: =IF(AND(J$7>=$D16,J$7<=$E16),1,"") | K16: =IF(AND(K$7>=$D16,K$7<=$E16),1,"") | L16: =IF(AND(L$7>=$D16,L$7<=$E16),1,"") | M16: =IF(AND(M$7>=$D16,M$7<=$E16),1,"") | N16: =IF(AND(N$7>=$D16,N$7<=$E16),1,"") | ... T16: =IF(AND(T$7>=$D16,T$7<=$E16),1,"")
A17: S2-10 | B17: =VLOOKUP($A17,Tareas!$A$8:$P$63,4,FALSE) -> Proteger galería y descarga WebP | C17: =VLOOKUP($A17,Tareas!$A$8:$P$63,5,FALSE) -> Geovanny | D17: =VLOOKUP($A17,Tareas!$A$8:$P$63,7,FALSE) -> 46290 | E17: =VLOOKUP($A17,Tareas!$A$8:$P$63,8,FALSE) -> 46290 | F17: =VLOOKUP($A17,Tareas!$A$8:$P$63,11,FALSE) -> Pendiente | G17: =IF(AND(G$7>=$D17,G$7<=$E17),1,"") | H17: =IF(AND(H$7>=$D17,H$7<=$E17),1,"") | I17: =IF(AND(I$7>=$D17,I$7<=$E17),1,"") | J17: =IF(AND(J$7>=$D17,J$7<=$E17),1,"") | K17: =IF(AND(K$7>=$D17,K$7<=$E17),1,"") | L17: =IF(AND(L$7>=$D17,L$7<=$E17),1,"") | M17: =IF(AND(M$7>=$D17,M$7<=$E17),1,"") | N17: =IF(AND(N$7>=$D17,N$7<=$E17),1,"") | ... T17: =IF(AND(T$7>=$D17,T$7<=$E17),1,"") -> 1
A18: S2-11 | B18: =VLOOKUP($A18,Tareas!$A$8:$P$63,4,FALSE) -> Preparar formularios y estados de interfaz | C18: =VLOOKUP($A18,Tareas!$A$8:$P$63,5,FALSE) -> Diego | D18: =VLOOKUP($A18,Tareas!$A$8:$P$63,7,FALSE) -> 46288 | E18: =VLOOKUP($A18,Tareas!$A$8:$P$63,8,FALSE) -> 46288 | F18: =VLOOKUP($A18,Tareas!$A$8:$P$63,11,FALSE) -> Pendiente | G18: =IF(AND(G$7>=$D18,G$7<=$E18),1,"") | H18: =IF(AND(H$7>=$D18,H$7<=$E18),1,"") | I18: =IF(AND(I$7>=$D18,I$7<=$E18),1,"") | J18: =IF(AND(J$7>=$D18,J$7<=$E18),1,"") | K18: =IF(AND(K$7>=$D18,K$7<=$E18),1,"") | L18: =IF(AND(L$7>=$D18,L$7<=$E18),1,"") | M18: =IF(AND(M$7>=$D18,M$7<=$E18),1,"") | N18: =IF(AND(N$7>=$D18,N$7<=$E18),1,"") | ... T18: =IF(AND(T$7>=$D18,T$7<=$E18),1,"")
A19: S2-12 | B19: =VLOOKUP($A19,Tareas!$A$8:$P$63,4,FALSE) -> Conectar acceso, Free, carga y galería | C19: =VLOOKUP($A19,Tareas!$A$8:$P$63,5,FALSE) -> Diego | D19: =VLOOKUP($A19,Tareas!$A$8:$P$63,7,FALSE) -> 46289 | E19: =VLOOKUP($A19,Tareas!$A$8:$P$63,8,FALSE) -> 46290 | F19: =VLOOKUP($A19,Tareas!$A$8:$P$63,11,FALSE) -> Pendiente | G19: =IF(AND(G$7>=$D19,G$7<=$E19),1,"") | H19: =IF(AND(H$7>=$D19,H$7<=$E19),1,"") | I19: =IF(AND(I$7>=$D19,I$7<=$E19),1,"") | J19: =IF(AND(J$7>=$D19,J$7<=$E19),1,"") | K19: =IF(AND(K$7>=$D19,K$7<=$E19),1,"") | L19: =IF(AND(L$7>=$D19,L$7<=$E19),1,"") | M19: =IF(AND(M$7>=$D19,M$7<=$E19),1,"") | N19: =IF(AND(N$7>=$D19,N$7<=$E19),1,"") | ... T19: =IF(AND(T$7>=$D19,T$7<=$E19),1,"") -> 1
... A23: S2-16 | B23: =VLOOKUP($A23,Tareas!$A$8:$P$63,4,FALSE) -> Corregir, revisar PR y presentar 30% | C23: =VLOOKUP($A23,Tareas!$A$8:$P$63,5,FALSE) -> Equipo | D23: =VLOOKUP($A23,Tareas!$A$8:$P$63,7,FALSE) -> 46290 | E23: =VLOOKUP($A23,Tareas!$A$8:$P$63,8,FALSE) -> 46290 | F23: =VLOOKUP($A23,Tareas!$A$8:$P$63,11,FALSE) -> Pendiente | G23: =IF(AND(G$7>=$D23,G$7<=$E23),1,"") | H23: =IF(AND(H$7>=$D23,H$7<=$E23),1,"") | I23: =IF(AND(I$7>=$D23,I$7<=$E23),1,"") | J23: =IF(AND(J$7>=$D23,J$7<=$E23),1,"") | K23: =IF(AND(K$7>=$D23,K$7<=$E23),1,"") | L23: =IF(AND(L$7>=$D23,L$7<=$E23),1,"") | M23: =IF(AND(M$7>=$D23,M$7<=$E23),1,"") | N23: =IF(AND(N$7>=$D23,N$7<=$E23),1,"") | ... T23: =IF(AND(T$7>=$D23,T$7<=$E23),1,"") -> 1

Sheet Tareas
A2: SmartStorage — Plan detallado de tareas
A3: Edita responsables, fechas, estado y evidencia. Los dos Gantt se actualizan por ID; conserva los identificadores.
A4: Fechas internas propuestas. Días calendario inclusivos; no representan horas ni dedicación exclusiva.
A5: Hecha requiere prueba local, revisión por un compañero y evidencia. Base verificada solo acredita el esqueleto.
A6: Ámbar: campos de seguimiento editables. Dependencias en la misma fecha requieren ejecución secuencial durante ese día.
A7: ID | B7: Hito | C7: Área | D7: Actividad | E7: Responsable | F7: Apoyo / coordinación | G7: Inicio propuesto | H7: Fin propuesto | I7: Días calendario | J7: Predecesoras | K7: Estado reportado | L7: Criterio de aceptación | M7: Evidencia / PR | N7: Fin de predecesoras | O7: Margen mínimo (d) | P7: Fuente
A8: S0-01 | B8: S0 | C8: Coordinación | D8: Definir equipo y organización | E8: Equipo | F8: Todos | G8: 46258 | H8: 46259 | I8: =IF(OR(G8="",H8=""),"",H8-G8+1) -> 2 | J8: — | K8: Hecha | L8: Integrantes y responsabilidades documentados. | O8: =IF(COUNT(G8:H8)<2,"Faltan fechas",MIN(H8-G8,VLOOKUP(B8,'Entregas y equipo'!$A$8:$D$13,4,FALSE)-H8,G8-N8)) -> 1 | P8: F1
A9: S0-02 | B9: S0 | C9: Propuesta | D9: Definir problema, solución y alcance | E9: Equipo | F9: Todos | G9: 46259 | H9: 46261 | I9: =IF(OR(G9="",H9=""),"",H9-G9+1) -> 3 | J9: S0-01 | K9: Hecha | L9: Propuesta Storage as a Service y alcance redactados. | N9: =MAX(VLOOKUP("S0-01",$A$8:$P$63,8,FALSE)) -> 46259 | O9: =IF(COUNT(G9:H9)<2,"Faltan fechas",MIN(H9-G9,VLOOKUP(B9,'Entregas y equipo'!$A$8:$D$13,4,FALSE)-H9,G9-N9)) -> 0 | P9: F1
A10: S0-03 | B10: S0 | C10: Planificación | D10: Preparar metodología y cronograma | E10: Equipo | F10: Todos | G10: 46260 | H10: 46261 | I10: =IF(OR(G10="",H10=""),"",H10-G10+1) -> 2 | J10: S0-01 | K10: Base verificada | L10: Scrum ligero, tablero Kanban e hitos acordados. | N10: =MAX(VLOOKUP("S0-01",$A$8:$P$63,8,FALSE)) -> 46259 | O10: =IF(COUNT(G10:H10)<2,"Faltan fechas",MIN(H10-G10,VLOOKUP(B10,'Entregas y equipo'!$A$8:$D$13,4,FALSE)-H10,G10-N10)) -> 1 | P10: F1
A11: S0-04 | B11: S0 | C11: Entrega | D11: Revisar y entregar propuesta | E11: Equipo | F11: Todos | G11: 46262 | H11: 46262 | I11: =IF(OR(G11="",H11=""),"",H11-G11+1) -> 1 | J11: S0-02, S0-03 | K11: Hecha | L11: Documento revisado y constancia de entrega disponible. | N11: =MAX(VLOOKUP("S0-02",$A$8:$P$63,8,FALSE),VLOOKUP("S0-03",$A$8:$P$63,8,FALSE)) -> 46261 | O11: =IF(COUNT(G11:H11)<2,"Faltan fechas",MIN(H11-G11,VLOOKUP(B11,'Entregas y equipo'!$A$8:$D$13,4,FALSE)-H11,G11-N11)) -> 0 | P11: F1
A12: S1-01 | B12: S1 | C12: Requisitos | D12: Detallar requisitos de usuarios | E12: Andy | F12: Diego | G12: 46265 | H12: 46268 | I12: =IF(OR(G12="",H12=""),"",H12-G12+1) -> 4 | J12: S0-04 | K12: Hecha | L12: Registro, acceso, verificación, recuperación y roles descritos. | N12: =MAX(VLOOKUP("S0-04",$A$8:$P$63,8,FALSE)) -> 46262 | O12: =IF(COUNT(G12:H12)<2,"Faltan fechas",MIN(H12-G12,VLOOKUP(B12,'Entregas y equipo'!$A$8:$D$13,4,FALSE)-H12,G12-N12)) -> 3 | P12: F1 + P1
A13: S1-02 | B13: S1 | C13: Requisitos | D13: Detallar requisitos de Storage | E13: Geovanny | F13: Andy | G13: 46265 | H13: 46268 | I13: =IF(OR(G13="",H13=""),"",H13-G13+1) -> 4 | J13: S0-04 | K13: Hecha | L13: Carga, formatos, deduplicación y permisos definidos. | N13: =MAX(VLOOKUP("S0-04",$A$8:$P$63,8,FALSE)) -> 46262 | O13: =IF(COUNT(G13:H13)<2,"Faltan fechas",MIN(H13-G13,VLOOKUP(B13,'Entregas y equipo'!$A$8:$D$13,4,FALSE)-H13,G13-N13)) -> 3 | P13: F1 + P1
A14: S1-03 | B14: S1 | C14: Requisitos | D14: Detallar planes y pagos simulados | E14: Elden | F14: Geovanny | G14: 46265 | H14: 46268 | I14: =IF(OR(G14="",H14=""),"",H14-G14+1) -> 4 | J14: S0-04 | K14: Por confirmar | L14: Catálogo, capacidades, suscripciones e historial especificados. | N14: =MAX(VLOOKUP("S0-04",$A$8:$P$63,8,FALSE)) -> 46262 | O14: =IF(COUNT(G14:H14)<2,"Faltan fechas",MIN(H14-G14,VLOOKUP(B14,'Entregas y equipo'!$A$8:$D$13,4,FALSE)-H14,G14-N14)) -> 3 | P14: F1 + P1
A15: S1-04 | B15: S1 | C15: Diseño | D15: Diseñar pantallas y navegación | E15: Diego | F15: Todos | G15: 46265 | H15: 46273 | I15: =IF(OR(G15="",H15=""),"",H15-G15+1) -> 9 | J15: S0-04 | K15: Por confirmar | L15: Mockups de acceso, biblioteca y planes revisados. | N15: =MAX(VLOOKUP("S0-04",$A$8:$P$63,8,FALSE)) -> 46262 | O15: =IF(COUNT(G15:H15)<2,"Faltan fechas",MIN(H15-G15,VLOOKUP(B15,'Entregas y equipo'!$A$8:$D$13,4,FALSE)-H15,G15-N15)) -> 3 | P15: F1 + P1
A16: S1-05 | B16: S1 | C16: Diseño | D16: Consolidar modelo de datos y arquitectura | E16: Equipo | F16: Todos | G16: 46269 | H16: 46274 | I16: =IF(OR(G16="",H16=""),"",H16-G16+1) -> 6 | J16: S1-01, S1-02, S1-03 | K16: Por confirmar | L16: Modelo relacional y arquitectura por capas consistentes. | N16: =MAX(VLOOKUP("S1-01",$A$8:$P$63,8,FALSE),VLOOKUP("S1-02",$A$8:$P$63,8,FALSE),VLOOKUP("S1-03",$A$8:$P$63,8,FALSE)) -> 46268 | O16: =IF(COUNT(G16:H16)<2,"Faltan fechas",MIN(H16-G16,VLOOKUP(B16,'Entregas y equipo'!$A$8:$D$13,4,FALSE)-H16,G16-N16)) -> 1 | P16: F1 + P1
A17: S1-06 | B17: S1 | C17: Entrega | D17: Revisar requisitos y diseño preliminar | E17: Equipo | F17: Todos | G17: 46275 | H17: 46276 | I17: =IF(OR(G17="",H17=""),"",H17-G17+1) -> 2 | J17: S1-04, S1-05 | K17: Por confirmar | L17: Documento y diagramas revisados. Adjuntar constancia de entrega. | N17: =MAX(VLOOKUP("S1-04",$A$8:$P$63,8,FALSE),VLOOKUP("S1-05",$A$8:$P$63,8,FALSE)) -> 46274 | O17: =IF(COUNT(G17:H17)<2,"Faltan fechas",MIN(H17-G17,VLOOKUP(B17,'Entregas y equipo'!$A$8:$D$13,4,FALSE)-H17,G17-N17)) -> 0 | P17: F1
A18: S2-01 | B18: S2 | C18: Base técnica | D18: Preparar esqueleto y esquema inicial | E18: Equipo | F18: Todos | G18: 46286 | H18: 46286 | I18: =IF(OR(G18="",H18=""),"",H18-G18+1) -> 1 | J18: — | K18: Base verificada | L18: React, API, migraciones y catálogo Free ejecutables. No demuestra el 30% funcional. | M18: README y verificacion.md: base ejecutable y comprobaciones registradas. | O18: =IF(COUNT(G18:H18)<2,"Faltan fechas",MIN(H18-G18,VLOOKUP(B18,'Entregas y equipo'!$A$8:$D$13,4,FALSE)-H18,G18-N18)) -> 0 | P18: F2 + F5
A19: S2-02 | B19: S2 | C19: Autenticación | D19: Implementar registro y hash seguro | E19: Andy | F19: Elden | G19: 46288 | H19: 46288 | I19: =IF(OR(G19="",H19=""),"",H19-G19+1) -> 1 | J19: S2-01 | K19: En progreso | L19: Validar datos y correo único. Guardar hash seguro. El registro público crea solo clientes. | N19: =MAX(VLOOKUP("S2-01",$A$8:$P$63,8,FALSE)) -> 46286 | O19: =IF(COUNT(G19:H19)<2,"Faltan fechas",MIN(H19-G19,VLOOKUP(B19,'Entregas y equipo'!$A$8:$D$13,4,FALSE)-H19,G19-N19)) -> 0 | P19: F3 + F6
A20: S2-03 | B20: S2 | C20: Autenticación | D20: Implementar login, JWT y protección | E20: Andy | F20: Diego | G20: 46289 | H20: 46289 | I20: =IF(OR(G20="",H20=""),"",H20-G20+1) -> 1 | J20: S2-02 | K20: En progreso | L20: Rechazar credenciales inválidas, JWT inválido/expirado y cuentas inactivas. Proteger /auth/me. | N20: =MAX(VLOOKUP("S2-02",$A$8:$P$63,8,FALSE)) -> 46288 | O20: =IF(COUNT(G20:H20)<2,"Faltan fechas",MIN(H20-G20,VLOOKUP(B20,'Entregas y equipo'!$A$8:$D$13,4,FALSE)-H20,G20-N20)) -> 0 | P20: F3 + F6
A21: S2-04 | B21: S2 | C21: Suscripciones | D21: Revisar catálogo y contrato de Free | E21: Elden | F21: Andy | G21: 46288 | H21: 46288 | I21: =IF(OR(G21="",H21=""),"",H21-G21+1) -> 1 | J21: S2-01 | K21: Planificada | L21: Free: 2 GB lógicos, 10 subidas y 200 MB diarios. Catálogo leído desde PostgreSQL. | N21: =MAX(VLOOKUP("S2-01",$A$8:$P$63,8,FALSE)) -> 46286 | O21: =IF(COUNT(G21:H21)<2,"Faltan fechas",MIN(H21-G21,VLOOKUP(B21,'Entregas y equipo'!$A$8:$D$13,4,FALSE)-H21,G21-N21)) -> 0 | P21: F3 + F4
A22: S2-05 | B22: S2 | C22: Suscripciones | D22: Asignar Free al registrar | E22: Elden | F22: Andy | G22: 46289 | H22: 46289 | I22: =IF(OR(G22="",H22=""),"",H22-G22+1) -> 1 | J22: S2-02, S2-04 | K22: Hecha | L22: Alta y asignación en una transacción. Una sola suscripción activa. Rollback ante error. | N22: =MAX(VLOOKUP("S2-02",$A$8:$P$63,8,FALSE),VLOOKUP("S2-04",$A$8:$P$63,8,FALSE)) -> 46288 | O22: =IF(COUNT(G22:H22)<2,"Faltan fechas",MIN(H22-G22,VLOOKUP(B22,'Entregas y equipo'!$A$8:$D$13,4,FALSE)-H22,G22-N22)) -> 0 | P22: F3 + F6
A23: S2-06 | B23: S2 | C23: Suscripciones | D23: Aplicar capacidad y límites diarios | E23: Elden | F23: Geovanny | G23: 46289 | H23: 46289 | I23: =IF(OR(G23="",H23=""),"",H23-G23+1) -> 1 | J23: S2-05 | K23: Pendiente | L23: Bloquear al exceder 2 GB, 10 subidas o 200 MB diarios. Probar límites y concurrencia. | N23: =MAX(VLOOKUP("S2-05",$A$8:$P$63,8,FALSE)) -> 46289 | O23: =IF(COUNT(G23:H23)<2,"Faltan fechas",MIN(H23-G23,VLOOKUP(B23,'Entregas y equipo'!$A$8:$D$13,4,FALSE)-H23,G23-N23)) -> 0 | P23: F3 + F4
A24: S2-07 | B24: S2 | C24: Storage | D24: Validar archivo y calcular SHA-256 | E24: Geovanny | F24: Andy | G24: 46288 | H24: 46288 | I24: =IF(OR(G24="",H24=""),"",H24-G24+1) -> 1 | J24: S2-01 | K24: Pendiente | L24: Aceptar JPG/PNG/WebP válidos, máximo 25 MB. Hash de los bytes originales antes de convertir. | N24: =MAX(VLOOKUP("S2-01",$A$8:$P$63,8,FALSE)) -> 46286 | O24: =IF(COUNT(G24:H24)<2,"Faltan fechas",MIN(H24-G24,VLOOKUP(B24,'Entregas y equipo'!$A$8:$D$13,4,FALSE)-H24,G24-N24)) -> 0 | P24: F3 + F4 + F6
A25: S2-08 | B25: S2 | C25: Storage | D25: Convertir a WebP y limpiar temporales | E25: Geovanny | F25: Elden | G25: 46289 | H25: 46289 | I25: =IF(OR(G25="",H25=""),"",H25-G25+1) -> 1 | J25: S2-07 | K25: Pendiente | L25: Conservar solo WebP definitivo. Eliminar original temporal al terminar y limpiar al fallar. | N25: =MAX(VLOOKUP("S2-07",$A$8:$P$63,8,FALSE)) -> 46288 | O25: =IF(COUNT(G25:H25)<2,"Faltan fechas",MIN(H25-G25,VLOOKUP(B25,'Entregas y equipo'!$A$8:$D$13,4,FALSE)-H25,G25-N25)) -> 0 | P25: F3 + F4
A26: S2-09 | B26: S2 | C26: Storage | D26: Integrar carga y deduplicación global | E26: Geovanny | F26: Andy y Elden | G26: 46289 | H26: 46289 | I26: =IF(OR(G26="",H26=""),"",H26-G26+1) -> 1 | J26: S2-03, S2-06, S2-08 | K26: Pendiente | L26: Dos cuentas con bytes idénticos referencian un único WebP. Conservar propiedad lógica y cuota. | N26: =MAX(VLOOKUP("S2-03",$A$8:$P$63,8,FALSE),VLOOKUP("S2-06",$A$8:$P$63,8,FALSE),VLOOKUP("S2-08",$A$8:$P$63,8,FALSE)) -> 46289 | O26: =IF(COUNT(G26:H26)<2,"Faltan fechas",MIN(H26-G26,VLOOKUP(B26,'Entregas y equipo'!$A$8:$D$13,4,FALSE)-H26,G26-N26)) -> 0 | P26: F3 + F4
A27: S2-10 | B27: S2 | C27: Storage | D27: Proteger galería y descarga WebP | E27: Geovanny | F27: Diego | G27: 46290 | H27: 46290 | I27: =IF(OR(G27="",H27=""),"",H27-G27+1) -> 1 | J27: S2-09 | K27: Pendiente | L27: Listar solo imágenes propias y negar acceso cruzado. Descargar WebP y conservar datos tras reinicio. | N27: =MAX(VLOOKUP("S2-09",$A$8:$P$63,8,FALSE)) -> 46289 | O27: =IF(COUNT(G27:H27)<2,"Faltan fechas",MIN(H27-G27,VLOOKUP(B27,'Entregas y equipo'!$A$8:$D$13,4,FALSE)-H27,G27-N27)) -> 0 | P27: F3 + F6
A28: S2-11 | B28: S2 | C28: Frontend | D28: Preparar formularios y estados de interfaz | E28: Diego | F28: Andy | G28: 46288 | H28: 46288 | I28: =IF(OR(G28="",H28=""),"",H28-G28+1) -> 1 | J28: S2-01 | K28: Pendiente | L28: Pantallas de registro/login y estados de carga/error acordes al contrato, sin éxito ficticio. | N28: =MAX(VLOOKUP("S2-01",$A$8:$P$63,8,FALSE)) -> 46286 | O28: =IF(COUNT(G28:H28)<2,"Faltan fechas",MIN(H28-G28,VLOOKUP(B28,'Entregas y equipo'!$A$8:$D$13,4,FALSE)-H28,G28-N28)) -> 0 | P28: F3 + F7
A29: S2-12 | B29: S2 | C29: Frontend | D29: Conectar acceso, Free, carga y galería | E29: Diego | F29: Todos | G29: 46289 | H29: 46290 | I29: =IF(OR(G29="",H29=""),"",H29-G29+1) -> 2 | J29: S2-03, S2-05, S2-11 | K29: Pendiente | L29: Registro → login → carga → galería → descarga con API real. Mensajes claros en errores. | N29: =MAX(VLOOKUP("S2-03",$A$8:$P$63,8,FALSE),VLOOKUP("S2-05",$A$8:$P$63,8,FALSE),VLOOKUP("S2-11",$A$8:$P$63,8,FALSE)) -> 46289 | O29: =IF(COUNT(G29:H29)<2,"Faltan fechas",MIN(H29-G29,VLOOKUP(B29,'Entregas y equipo'!$A$8:$D$13,4,FALSE)-H29,G29-N29)) -> 0 | P29: F3
A30: S2-13 | B30: S2 | C30: Administrador | D30: Calcular ahorro básico del administrador | E30: Geovanny | F30: Diego | G30: 46290 | H30: 46290 | I30: =IF(OR(G30="",H30=""),"",H30-G30+1) -> 1 | J30: S2-09 | K30: Pendiente | L30: Solo admin: B−P y porcentaje con originales lógicos y bytes WebP reales. Biblioteca vacía y archivo faltante tratados. | N30: =MAX(VLOOKUP("S2-09",$A$8:$P$63,8,FALSE)) -> 46289 | O30: =IF(COUNT(G30:H30)<2,"Faltan fechas",MIN(H30-G30,VLOOKUP(B30,'Entregas y equipo'!$A$8:$D$13,4,FALSE)-H30,G30-N30)) -> 0 | P30: F3 + F4
A31: S2-14 | B31: S2 | C31: Documentación | D31: Actualizar requisitos y diagramas | E31: Equipo | F31: Cada responsable | G31: 46288 | H31: 46289 | I31: =IF(OR(G31="",H31=""),"",H31-G31+1) -> 2 | J31: S2-01 | K31: Pendiente | L31: Alinear documentación: deduplicación global, solo WebP, ahorro administrativo y esquema incremental. | N31: =MAX(VLOOKUP("S2-01",$A$8:$P$63,8,FALSE)) -> 46286 | O31: =IF(COUNT(G31:H31)<2,"Faltan fechas",MIN(H31-G31,VLOOKUP(B31,'Entregas y equipo'!$A$8:$D$13,4,FALSE)-H31,G31-N31)) -> 1 | P31: F4
A32: S2-15 | B32: S2 | C32: Verificación | D32: Probar flujo del 30% con dos cuentas | E32: Equipo | F32: Todos | G32: 46290 | H32: 46290 | I32: =IF(OR(G32="",H32=""),"",H32-G32+1) -> 1 | J32: S2-10, S2-12, S2-13, S2-14 | K32: Pendiente | L32: Verificar identidad, Free/límites, carga duplicada, permisos, descarga, ahorro y reinicio. Registrar evidencia. | N32: =MAX(VLOOKUP("S2-10",$A$8:$P$63,8,FALSE),VLOOKUP("S2-12",$A$8:$P$63,8,FALSE),VLOOKUP("S2-13",$A$8:$P$63,8,FALSE),VLOOKUP("S2-14",$A$8:$P$63,8,FALSE)) -> 46290 | O32: =IF(COUNT(G32:H32)<2,"Faltan fechas",MIN(H32-G32,VLOOKUP(B32,'Entregas y equipo'!$A$8:$D$13,4,FALSE)-H32,G32-N32)) -> 0 | P32: F3
A33: S2-16 | B33: S2 | C33: Entrega | D33: Corregir, revisar PR y presentar 30% | E33: Equipo | F33: Todos | G33: 46290 | H33: 46290 | I33: =IF(OR(G33="",H33=""),"",H33-G33+1) -> 1 | J33: S2-15 | K33: Pendiente | L33: Corregir bloqueos, revisión por compañero, ejecución local, demo y constancia de entrega. | N33: =MAX(VLOOKUP("S2-15",$A$8:$P$63,8,FALSE)) -> 46290 | O33: =IF(COUNT(G33:H33)<2,"Faltan fechas",MIN(H33-G33,VLOOKUP(B33,'Entregas y equipo'!$A$8:$D$13,4,FALSE)-H33,G33-N33)) -> 0 | P33: F1 + F3 + F8
A34: S3-01 | B34: S3 | C34: Autenticación | D34: Implementar verificación de correo | E34: Andy | F34: Diego | G34: 46293 | H34: 46295 | I34: =IF(OR(G34="",H34=""),"",H34-G34+1) -> 3 | J34: S2-16 | K34: Planificada | L34: Token de un uso, expiración, correo y estados de interfaz verificados. | N34: =MAX(VLOOKUP("S2-16",$A$8:$P$63,8,FALSE)) -> 46290 | O34: =IF(COUNT(G34:H34)<2,"Faltan fechas",MIN(H34-G34,VLOOKUP(B34,'Entregas y equipo'!$A$8:$D$13,4,FALSE)-H34,G34-N34)) -> 2 | P34: F1 + F3
A35: S3-02 | B35: S3 | C35: Autenticación | D35: Recuperar y cambiar contraseña | E35: Andy | F35: Diego | G35: 46296 | H35: 46300 | I35: =IF(OR(G35="",H35=""),"",H35-G35+1) -> 5 | J35: S3-01 | K35: Planificada | L35: Solicitud neutral, token único, contraseña segura y flujo de recuperación probado. | N35: =MAX(VLOOKUP("S3-01",$A$8:$P$63,8,FALSE)) -> 46295 | O35: =IF(COUNT(G35:H35)<2,"Faltan fechas",MIN(H35-G35,VLOOKUP(B35,'Entregas y equipo'!$A$8:$D$13,4,FALSE)-H35,G35-N35)) -> 1 | P35: F3 + F6
A36: S3-03 | B36: S3 | C36: Autenticación | D36: Completar sesiones revocables y logout | E36: Andy | F36: Diego | G36: 46301 | H36: 46302 | I36: =IF(OR(G36="",H36=""),"",H36-G36+1) -> 2 | J36: S3-02 | K36: Planificada | L36: Revocar sesión en backend y limpiar cliente. Comprobar expiración y acceso después de logout. | N36: =MAX(VLOOKUP("S3-02",$A$8:$P$63,8,FALSE)) -> 46300 | O36: =IF(COUNT(G36:H36)<2,"Faltan fechas",MIN(H36-G36,VLOOKUP(B36,'Entregas y equipo'!$A$8:$D$13,4,FALSE)-H36,G36-N36)) -> 1 | P36: F3 + F4 + F6
A37: S3-04 | B37: S3 | C37: Storage | D37: Implementar Redis, BullMQ y worker Sharp | E37: Geovanny | F37: Elden | G37: 46293 | H37: 46296 | I37: =IF(OR(G37="",H37=""),"",H37-G37+1) -> 4 | J37: S2-16 | K37: Planificada | L37: Procesamiento asíncrono real y estados persistentes de trabajo. | N37: =MAX(VLOOKUP("S2-16",$A$8:$P$63,8,FALSE)) -> 46290 | O37: =IF(COUNT(G37:H37)<2,"Faltan fechas",MIN(H37-G37,VLOOKUP(B37,'Entregas y equipo'!$A$8:$D$13,4,FALSE)-H37,G37-N37)) -> 3 | P37: F3
A38: S3-05 | B38: S3 | C38: Storage | D38: Añadir reintentos y recuperación de trabajos | E38: Geovanny | F38: Elden | G38: 46297 | H38: 46300 | I38: =IF(OR(G38="",H38=""),"",H38-G38+1) -> 4 | J38: S3-04 | K38: Planificada | L38: Recuperar interrupciones, no duplicar objetos y limpiar temporales fallidos o expirados. | N38: =MAX(VLOOKUP("S3-04",$A$8:$P$63,8,FALSE)) -> 46296 | O38: =IF(COUNT(G38:H38)<2,"Faltan fechas",MIN(H38-G38,VLOOKUP(B38,'Entregas y equipo'!$A$8:$D$13,4,FALSE)-H38,G38-N38)) -> 1 | P38: F3 + F4
A39: S3-06 | B39: S3 | C39: Storage | D39: Implementar borrado con referencias | E39: Geovanny | F39: Andy | G39: 46301 | H39: 46301 | I39: =IF(OR(G39="",H39=""),"",H39-G39+1) -> 1 | J39: S3-05 | K39: Planificada | L39: Borrar imagen lógica. Eliminar WebP solo al quitar la última referencia con coordinación transaccional. | N39: =MAX(VLOOKUP("S3-05",$A$8:$P$63,8,FALSE)) -> 46300 | O39: =IF(COUNT(G39:H39)<2,"Faltan fechas",MIN(H39-G39,VLOOKUP(B39,'Entregas y equipo'!$A$8:$D$13,4,FALSE)-H39,G39-N39)) -> 0 | P39: F3 + F4
A40: S3-07 | B40: S3 | C40: Storage | D40: Crear álbumes y mover imágenes | E40: Geovanny | F40: Diego | G40: 46302 | H40: 46302 | I40: =IF(OR(G40="",H40=""),"",H40-G40+1) -> 1 | J40: S3-06 | K40: Planificada | L40: Crear carpetas y mover imágenes propias. Rechazar carpeta o imagen de otra cuenta. | N40: =MAX(VLOOKUP("S3-06",$A$8:$P$63,8,FALSE)) -> 46301 | O40: =IF(COUNT(G40:H40)<2,"Faltan fechas",MIN(H40-G40,VLOOKUP(B40,'Entregas y equipo'!$A$8:$D$13,4,FALSE)-H40,G40-N40)) -> 0 | P40: F1 + F3
A41: S3-08 | B41: S3 | C41: Suscripciones | D41: Integrar cuotas con trabajos asíncronos | E41: Elden | F41: Geovanny | G41: 46293 | H41: 46300 | I41: =IF(OR(G41="",H41=""),"",H41-G41+1) -> 8 | J41: S2-16 | K41: Planificada | L41: Mantener capacidad y límites consistentes con subidas concurrentes y trabajos fallidos. | N41: =MAX(VLOOKUP("S2-16",$A$8:$P$63,8,FALSE)) -> 46290 | O41: =IF(COUNT(G41:H41)<2,"Faltan fechas",MIN(H41-G41,VLOOKUP(B41,'Entregas y equipo'!$A$8:$D$13,4,FALSE)-H41,G41-N41)) -> 3 | P41: F3 + F4 + P1
...

Sheet Entregas y equipo
A2: SmartStorage — Entregas y equipo
A3: Fecha de revisión: | C3: 46288
A4: 30%, 50% y 80% son metas de entrega; no son porcentajes medidos de implementación.
A5: 06/11/2026 es tentativo. El documento fija únicamente la primera semana de noviembre.
A7: Hito | B7: Entrega | C7: Inicio de sprint | D7: Fecha límite | E7: Meta acumulada | F7: Alcance de la entrega | G7: Origen de la fecha | H7: Tareas del plan | I7: Hechas con evidencia
A8: S0 | B8: Coordinación y propuesta | C8: 46258 | D8: 46262 | F8: Equipo, propuesta, alcance y cronograma. | G8: Fecha del documento | H8: =COUNTIFS(Tareas!$B$8:$B$63,A8) -> 4 | I8: =COUNTIFS(Tareas!$B$8:$B$63,A8,Tareas!$K$8:$K$63,"Hecha",Tareas!$M$8:$M$63,"<>") -> 0
A9: S1 | B9: Requisitos y diseño preliminar | C9: 46263 | D9: 46276 | F9: Requisitos, diagramas, arquitectura y mockups. | G9: Fecha del documento | H9: =COUNTIFS(Tareas!$B$8:$B$63,A9) -> 6 | I9: =COUNTIFS(Tareas!$B$8:$B$63,A9,Tareas!$K$8:$K$63,"Hecha",Tareas!$M$8:$M$63,"<>") -> 0
A10: S2 | B10: Avance funcional 1 (30%) | C10: 46277 | D10: 46290 | E10: 0.3 | F10: Registro, login, Free, límites, WebP, deduplicación, galería, descarga y ahorro básico de administrador. | G10: Fecha del documento | H10: =COUNTIFS(Tareas!$B$8:$B$63,A10) -> 16 | I10: =COUNTIFS(Tareas!$B$8:$B$63,A10,Tareas!$K$8:$K$63,"Hecha",Tareas!$M$8:$M$63,"<>") -> 0
A11: S3 | B11: Avance funcional 2 (50%) | C11: 46291 | D11: 46304 | E11: 0.5 | F11: Propuesta: seguridad de cuentas, sesiones revocables, worker, reintentos, borrado y álbumes. | G11: Fecha del documento | H11: =COUNTIFS(Tareas!$B$8:$B$63,A11) -> 12 | I11: =COUNTIFS(Tareas!$B$8:$B$63,A11,Tareas!$K$8:$K$63,"Hecha",Tareas!$M$8:$M$63,"<>") -> 0
A12: S4 | B12: Avance funcional 3 (80%) | C12: 46305 | D12: 46318 | E12: 0.8 | F12: Propuesta: pagos simulados, historial, renovación, cambios de plan y panel administrador. | G12: Fecha del documento | H12: =COUNTIFS(Tareas!$B$8:$B$63,A12) -> 10 | I12: =COUNTIFS(Tareas!$B$8:$B$63,A12,Tareas!$K$8:$K$63,"Hecha",Tareas!$M$8:$M$63,"<>") -> 0
A13: S5 | B13: Entrega final y exposiciones | C13: 46319 | D13: 46332 | E13: 1 | F13: Propuesta: estabilización, documentación, demo técnica y exposición. | G13: 06/11 tentativo (imagen) | H13: =COUNTIFS(Tareas!$B$8:$B$63,A13) -> 8 | I13: =COUNTIFS(Tareas!$B$8:$B$63,A13,Tareas!$K$8:$K$63,"Hecha",Tareas!$M$8:$M$63,"<>") -> 0
A15: Responsabilidades del equipo
A17: Nombre corto | B17: Integrante | C17: Carnet | D17: Área principal | E17: Tareas asignadas | F17: Responsabilidad documentada
A18: Andy | B18: Andy Isaac Monzón Lopez | C18: 1539522 | D18: Auth | E18: =COUNTIFS(Tareas!$E$8:$E$63,A18) -> 8 | F18: Registro, login, validaciones, JWT, middleware y seguridad de cuentas.
A19: Geovanny | B19: Justo Geovanny Alcon Mendoza | C19: 1578324 | D19: Storage | E19: =COUNTIFS(Tareas!$E$8:$E$63,A19) -> 13 | F19: Carga, hash, WebP, deduplicación, archivos, workers y métricas de almacenamiento.
A20: Elden | B20: Elden Eduardo Gil Soto | C20: 1641123 | D20: Planes | E20: =COUNTIFS(Tareas!$E$8:$E$63,A20) -> 9 | F20: Catálogo, Free, límites, suscripciones y pagos simulados.
A21: Diego | B21: Diego Jose Alegria Oros | C21: 1631524 | D21: Frontend | E21: =COUNTIFS(Tareas!$E$8:$E$63,A21) -> 8 | F21: Tema, componentes, navegación, pantallas e integración del frontend.
A23: Criterios del cronograma
A25: El reparto de módulos se conserva. “Diego” y “Alegría” corresponden al mismo integrante. No se añade un quinto miembro.
A26: S0/S1: descomposición histórica propuesta; la existencia del documento no confirma que se haya entregado o aprobado.
A27: S2: alcance del 30% tomado de avance-30.md. La base técnica verificada no equivale al recorrido funcional completo.
A28: S2: cierre propuesto del 23 al 25/09. Requiere coordinación el mismo día; la disponibilidad del equipo no está cuantificada.
A29: S3/S4/S5: distribución propuesta de los hitos siguientes. Confirmar demo SDK/API y precios antes de implementarlos.
A30: Los inicios de sprint y las fechas internas son de planificación. Solo los límites S0–S4 están fechados en el documento.
A31: Dependencias: fin→inicio, permitiendo secuencia en el mismo día. No son un cálculo automático de ruta crítica.
A32: Weekly: una reunión por semana para avances/bloqueos, más retrospectiva de 10–15 min. Acordar día y hora con el equipo.
A33: Antes de cada entrega: demostración interna, pruebas locales y revisión por al menos un compañero.
A34: Al actualizar dependencias en J de Tareas, ajustar también la fórmula de N. Para nuevas filas, ampliar Gantt y rangos.
A35: Margen mínimo (Tareas, O): menor margen entre duración, límite del hito y predecesoras. Un valor negativo señala conflicto.
A38: Fuentes y procedencia
A40: F1 | B40: Proyecto - Ing. Software.docx: tabla de estudiantes, cronograma, alcance y metodología.
A41: F2 | B41: README.md: estado de la base técnica, decisiones confirmadas y reparto del equipo.
A42: F3 | B42: docs/avance-30.md: recorrido de aceptación, reparto, orden de integración e hitos siguientes.
